Workbook

Sheet NPC (2)
A1: Conta | B1: Descrição | C1: Janeiro | D1: Fevereiro | E1: Março | F1: Abril | G1: Maio | H1: Junho | I1: Julho | J1: Agosto | K1: Setembro | L1: Outubro | M1: Novembro | N1: Dezembro | O1: 1TRI 25 | P1: 2TRI 25 | Q1: 3TRI 25 | R1: 4TRI 25 | S1: Acumulado | T1: Orçado Planejamento | U1: Diferença | V1: Orçado Unimed | W1: Diferença
A2: (+) 010 | B2: Receita Bruta Operacional | C2: 1477175.9 | D2: 1588602.8 | E2: 1365786.2 | F2: 1787262.1 | G2: 1640961.8 | H2: 1787215.6 | O2: =SUM(C2:E2) -> 4431564.9 | P2: =SUM(F2:H2) -> 5215439.6 | Q2: =SUM(I2:K2) -> 0 | R2: =SUM(L2:N2) -> 0 | S2: =SUM(C2:N2) -> 9647004.5 | T2: 10054758 | U2: =S2-T2 -> -407753.51 | V2: 8682000 | W2: =S2-V2 -> 965004.49
A3: 010.01 | B3: Faturamento Prod. Merc. e Serviços | C3: 1477175.9 | D3: 1588602.8 | E3: 1365786.2 | F3: 1787262.1 | G3: 1640961.8 | H3: 1787215.6 | O3: =SUM(C3:E3) -> 4431564.9 | P3: =SUM(F3:H3) -> 5215439.6 | Q3: =SUM(I3:K3) -> 0 | R3: =SUM(L3:N3) -> 0 | S3: =SUM(C3:N3) -> 9647004.5
A4: 010.01.03 | B4: Vendas de Serviços | C4: 1471175.9 | D4: 1585602.8 | E4: 1362786.2 | F4: 1787262.1 | G4: 1640961.8 | H4: 1787215.6 | O4: =SUM(C4:E4) -> 4419564.9 | P4: =SUM(F4:H4) -> 5215439.6 | Q4: =SUM(I4:K4) -> 0 | R4: =SUM(L4:N4) -> 0 | S4: =SUM(C4:N4) -> 9635004.5
A5: 3.01.01.01.01.0006 | B5: Receita da Prestação de Serviços - Mercado Interno | C5: 1471175.9 | D5: 1585602.8 | E5: 1362786.2 | F5: 1787262.1 | G5: 1640961.8 | H5: 1787215.6 | O5: =SUM(C5:E5) -> 4419564.9 | P5: =SUM(F5:H5) -> 5215439.6 | Q5: =SUM(I5:K5) -> 0 | R5: =SUM(L5:N5) -> 0 | S5: =SUM(C5:N5) -> 9635004.5
A6: 010.01.06 | B6: Locação de Bens Móveis e Imóveis | C6: 6000 | D6: 3000 | E6: 3000 | O6: =SUM(C6:E6) -> 12000 | P6: =SUM(F6:H6) -> 0 | Q6: =SUM(I6:K6) -> 0 | R6: =SUM(L6:N6) -> 0 | S6: =SUM(C6:N6) -> 12000
A7: 3.01.01.01.01.0008 | B7: Receita de Locação de Bens Móveis e Imóveis | C7: 6000 | D7: 3000 | E7: 3000 | O7: =SUM(C7:E7) -> 12000 | P7: =SUM(F7:H7) -> 0 | Q7: =SUM(I7:K7) -> 0 | R7: =SUM(L7:N7) -> 0 | S7: =SUM(C7:N7) -> 12000
A8: (-) 020 | B8: Deduções da Receita | C8: 97833.22 | D8: 105442.54 | E8: 90625.19 | F8: 118835.87 | G8: 109123.99 | H8: 118849.76 | O8: =SUM(C8:E8) -> 293900.95 | P8: =SUM(F8:H8) -> 346809.62 | Q8: =SUM(I8:K8) -> 0 | R8: =SUM(L8:N8) -> 0 | S8: =SUM(C8:N8) -> 640710.57
A9: 020.01 | B9: Impostos Faturados | C9: 97833.22 | D9: 105442.54 | E9: 90625.19 | O9: =SUM(C9:E9) -> 293900.95 | P9: =SUM(F9:H9) -> 0 | Q9: =SUM(I9:K9) -> 0 | R9: =SUM(L9:N9) -> 0 | S9: =SUM(C9:N9) -> 293900.95
A10: 020.01.02 | B10: ISS | C10: 44135.3 | D10: 47568.04 | E10: 40883.49 | F10: 53610.16 | G10: 49228.88 | H10: 53616.39 | O10: =SUM(C10:E10) -> 132586.83 | P10: =SUM(F10:H10) -> 156455.43 | Q10: =SUM(I10:K10) -> 0 | R10: =SUM(L10:N10) -> 0 | S10: =SUM(C10:N10) -> 289042.26
A11: 3.01.01.01.03.0005 | B11: ISS | C11: 44135.3 | D11: 47568.04 | E11: 40883.49 | O11: =SUM(C11:E11) -> 132586.83 | P11: =SUM(F11:H11) -> 0 | Q11: =SUM(I11:K11) -> 0 | R11: =SUM(L11:N11) -> 0 | S11: =SUM(C11:N11) -> 132586.83
A12: 020.01.03 | B12: COFINS | C12: 44135.28 | D12: 47568.08 | E12: 40883.59 | F12: 53610.17 | G12: 49228.86 | H12: 53616.47 | O12: =SUM(C12:E12) -> 132586.95 | P12: =SUM(F12:H12) -> 156455.5 | Q12: =SUM(I12:K12) -> 0 | R12: =SUM(L12:N12) -> 0 | S12: =SUM(C12:N12) -> 289042.45
A13: 3.01.01.01.03.0003 | B13: COFINS | C13: 44135.28 | D13: 47568.08 | E13: 40883.59 | O13: =SUM(C13:E13) -> 132586.95 | P13: =SUM(F13:H13) -> 0 | Q13: =SUM(I13:K13) -> 0 | R13: =SUM(L13:N13) -> 0 | S13: =SUM(C13:N13) -> 132586.95
A14: 020.01.04 | B14: PIS | C14: 9562.64 | D14: 10306.42 | E14: 8858.11 | F14: 11615.54 | G14: 10666.25 | H14: 11616.9 | O14: =SUM(C14:E14) -> 28727.17 | P14: =SUM(F14:H14) -> 33898.69 | Q14: =SUM(I14:K14) -> 0 | R14: =SUM(L14:N14) -> 0 | S14: =SUM(C14:N14) -> 62625.86
A15: 3.01.01.01.03.0004 | B15: PIS/PASEP | C15: 9562.64 | D15: 10306.42 | E15: 8858.11 | O15: =SUM(C15:E15) -> 28727.17 | P15: =SUM(F15:H15) -> 0 | Q15: =SUM(I15:K15) -> 0 | R15: =SUM(L15:N15) -> 0 | S15: =SUM(C15:N15) -> 28727.17
A16: (=) 030 | B16: Receita Líquida | C16: 1379342.7 | D16: 1483160.2 | E16: 1275161 | F16: 1668426.2 | G16: 1531837.9 | H16: 1668365.9 | O16: =SUM(C16:E16) -> 4137664 | P16: =SUM(F16:H16) -> 4868630 | Q16: =SUM(I16:K16) -> 0 | R16: =SUM(L16:N16) -> 0 | S16: =SUM(C16:N16) -> 9006293.9
A17: (-) 040 | B17: Custo Mercad./Serv./Produtos Vendidos | C17: 670896.37 | D17: 550631.43 | E17: 659749.75 | F17: 662933.9 | G17: 572212.66 | H17: 608013.49 | O17: =SUM(C17:E17) -> 1881277.6 | P17: =SUM(F17:H17) -> 1843160.1 | Q17: =SUM(I17:K17) -> 0 | R17: =SUM(L17:N17) -> 0 | S17: =SUM(C17:N17) -> 3724437.6 | T17: =S17/S16 -> 0.4135372
A18: 040.03 | B18: Custo dos Serviços Prestados | C18: 670896.37 | D18: 550631.43 | E18: 659749.75 | O18: =SUM(C18:E18) -> 1881277.6 | P18: =SUM(F18:H18) -> 0 | Q18: =SUM(I18:K18) -> 0 | R18: =SUM(L18:N18) -> 0 | S18: =SUM(C18:N18) -> 1881277.6
A19: 3.01.01.03.06 | B19: Custo dos Serviços Produzidos | C19: 670896.37 | D19: 550631.43 | E19: 659749.75 | O19: =SUM(C19:E19) -> 1881277.6 | P19: =SUM(F19:H19) -> 0 | Q19: =SUM(I19:K19) -> 0 | R19: =SUM(L19:N19) -> 0 | S19: =SUM(C19:N19) -> 1881277.6
A20: 3.01.01.03.06.0008 | B20: Serviços Prestados Pessoa Jurídica | C20: 297917.8 | D20: 252772.9 | E20: 263222.53 | O20: =SUM(C20:E20) -> 813913.23 | P20: =SUM(F20:H20) -> 0 | Q20: =SUM(I20:K20) -> 0 | R20: =SUM(L20:N20) -> 0 | S20: =SUM(C20:N20) -> 813913.23
A21: 3.01.01.03.06.0011 | B21: INSS - Previdência Social | C21: 88026.4 | D21: 65873.66 | E21: 63210.84 | O21: =SUM(C21:E21) -> 217110.9 | P21: =SUM(F21:H21) -> 0 | Q21: =SUM(I21:K21) -> 0 | R21: =SUM(L21:N21) -> 0 | S21: =SUM(C21:N21) -> 217110.9
A22: 3.01.01.03.06.0012 | B22: FGTS | C22: 22923.83 | D22: 27467.39 | E22: 19568.04 | O22: =SUM(C22:E22) -> 69959.26 | P22: =SUM(F22:H22) -> 0 | Q22: =SUM(I22:K22) -> 0 | R22: =SUM(L22:N22) -> 0 | S22: =SUM(C22:N22) -> 69959.26
A23: 3.01.01.03.06.0014 | B23: Alimentação do Trabalhador | C23: 13750 | D23: 13482 | E23: 65259.45 | O23: =SUM(C23:E23) -> 92491.45 | P23: =SUM(F23:H23) -> 0 | Q23: =SUM(I23:K23) -> 0 | R23: =SUM(L23:N23) -> 0 | S23: =SUM(C23:N23) -> 92491.45
A24: 3.01.01.03.06.0040 | B24: Ordenados, Salários e Gratificações | C24: 164865.21 | D24: 127902.66 | E24: 172050.49 | O24: =SUM(C24:E24) -> 464818.36 | P24: =SUM(F24:H24) -> 0 | Q24: =SUM(I24:K24) -> 0 | R24: =SUM(L24:N24) -> 0 | S24: =SUM(C24:N24) -> 464818.36
A25: 3.01.01.03.06.0041 | B25: Férias | C25: 0 | D25: 0 | E25: 29157.27 | O25: =SUM(C25:E25) -> 29157.27 | P25: =SUM(F25:H25) -> 0 | Q25: =SUM(I25:K25) -> 0 | R25: =SUM(L25:N25) -> 0 | S25: =SUM(C25:N25) -> 29157.27
A26: 3.01.01.03.06.0042 | B26: Décimo Terceiro Salário | C26: 0 | D26: 0 | E26: 19601.83 | O26: =SUM(C26:E26) -> 19601.83 | P26: =SUM(F26:H26) -> 0 | Q26: =SUM(I26:K26) -> 0 | R26: =SUM(L26:N26) -> 0 | S26: =SUM(C26:N26) -> 19601.83
A27: 3.01.01.03.06.0043 | B27: Outros Gastos com Pessoal Ligado à Produção de Serviços | C27: 53281.25 | D27: 26995.44 | E27: 9267 | O27: =SUM(C27:E27) -> 89543.69 | P27: =SUM(F27:H27) -> 0 | Q27: =SUM(I27:K27) -> 0 | R27: =SUM(L27:N27) -> 0 | S27: =SUM(C27:N27) -> 89543.69
A28: 3.01.01.03.06.0045 | B28: Vale Transporte | C28: 1337.25 | D28: 868.1 | E28: -1260.57 | O28: =SUM(C28:E28) -> 944.78 | P28: =SUM(F28:H28) -> 0 | Q28: =SUM(I28:K28) -> 0 | R28: =SUM(L28:N28) -> 0 | S28: =SUM(C28:N28) -> 944.78
A29: 3.01.01.03.06.0047 | B29: Assistência Médica e Odontológica | C29: 5113.23 | D29: 12463.33 | E29: 4355.24 | O29: =SUM(C29:E29) -> 21931.8 | P29: =SUM(F29:H29) -> 0 | Q29: =SUM(I29:K29) -> 0 | R29: =SUM(L29:N29) -> 0 | S29: =SUM(C29:N29) -> 21931.8
A30: 3.01.01.03.06.0048 | B30: Rescisão de Contrato de Trabalho | C30: 23681.4 | D30: 22805.95 | E30: 15330.41 | O30: =SUM(C30:E30) -> 61817.76 | P30: =SUM(F30:H30) -> 0 | Q30: =SUM(I30:K30) -> 0 | R30: =SUM(L30:N30) -> 0 | S30: =SUM(C30:N30) -> 61817.76
A31: (=) 060 | B31: Lucro Bruto | C31: 708446.32 | D31: 932528.82 | E31: 615411.27 | F31: 1005492.3 | G31: 959625.19 | H31: 1060352.4 | O31: =SUM(C31:E31) -> 2256386.4 | P31: =SUM(F31:H31) -> 3025469.9 | Q31: =SUM(I31:K31) -> 0 | R31: =SUM(L31:N31) -> 0 | S31: =SUM(C31:N31) -> 5281856.3
A32: (-) 070 | B32: Despesas Operacionais | C32: 539659.25 | D32: 824192.58 | E32: 574253.27 | F32: 501883.86 | G32: 544990.72 | H32: 636234.54 | O32: =SUM(C32:E32) -> 1938105.1 | P32: =SUM(F32:H32) -> 1683109.1 | Q32: =SUM(I32:K32) -> 0 | R32: =SUM(L32:N32) -> 0 | S32: =SUM(C32:N32) -> 3621214.2
A33: 070.01 | B33: Despesas Administrativas | C33: 378622.09 | D33: 641868.66 | E33: 416957.3 | O33: =SUM(C33:E33) -> 1437448.1 | P33: =SUM(F33:H33) -> 0 | Q33: =SUM(I33:K33) -> 0 | R33: =SUM(L33:N33) -> 0 | S33: =SUM(C33:N33) -> 1437448.1 | T33: =C32-C65-C73 -> 378622.09 | U33: =D32-D65-D73 -> 641868.66 | V33: =E32-E65-E73 -> 416957.3 | W33: =F32 -> 501883.86 | X33: =G32 -> 544990.72 | Y33: =H32 -> 636234.54
A34: 3.01.01.07.01 | B34: Despesas Operacionais das Atividades em Geral | C34: 304789.01 | D34: 614109.22 | E34: 400240.46 | O34: =SUM(C34:E34) -> 1319138.7 | P34: =SUM(F34:H34) -> 0 | Q34: =SUM(I34:K34) -> 0 | R34: =SUM(L34:N34) -> 0 | S34: =SUM(C34:N34) -> 1319138.7
A35: 3.01.01.07.01.0003 | B35: Ordenados, Salários, Gratif e Outras Remuner a Empregados | C35: 108353.66 | D35: 106723.65 | E35: 66104.57 | O35: =SUM(C35:E35) -> 281181.88 | P35: =SUM(F35:H35) -> 0 | Q35: =SUM(I35:K35) -> 0 | R35: =SUM(L35:N35) -> 0 | S35: =SUM(C35:N35) -> 281181.88
A36: 3.01.01.07.01.0009 | B36: Serviços Prestados Pessoa Jurídica | C36: 88794.54 | D36: 405733.11 | E36: 263222.53 | F36: 165874.32 | G36: 0 | H36: 0 | O36: =SUM(C36:E36) -> 757750.18 | P36: =SUM(F36:H36) -> 165874.32 | Q36: =SUM(I36:K36) -> 0 | R36: =SUM(L36:N36) -> 0 | S36: =SUM(C36:N36) -> 923624.5
A37: 3.01.01.07.01.0024 | B37: Aluguéis | C37: 66215.21 | D37: 64715.21 | E37: 64715.21 | O37: =SUM(C37:E37) -> 195645.63 | P37: =SUM(F37:H37) -> 0 | Q37: =SUM(I37:K37) -> 0 | R37: =SUM(L37:N37) -> 0 | S37: =SUM(C37:N37) -> 195645.63
A38: 3.01.01.07.01.0029 | B38: Multas | C38: 0 | D38: 106.3 | E38: 0 | O38: =SUM(C38:E38) -> 106.3 | P38: =SUM(F38:H38) -> 0 | Q38: =SUM(I38:K38) -> 0 | R38: =SUM(L38:N38) -> 0 | S38: =SUM(C38:N38) -> 106.3
A39: 3.01.01.07.01.0030 | B39: Encargos de Depreciação e Amortização | C39: 3152.09 | D39: 3440.66 | E39: 3440.66 | O39: =SUM(C39:E39) -> 10033.41 | P39: =SUM(F39:H39) -> 0 | Q39: =SUM(I39:K39) -> 0 | R39: =SUM(L39:N39) -> 0 | S39: =SUM(C39:N39) -> 10033.41
A40: 3.01.01.07.01.0042 | B40: Outras Despesas Operacionais | C40: 0 | D40: 0 | E40: 430 | O40: =SUM(C40:E40) -> 430 | P40: =SUM(F40:H40) -> 0 | Q40: =SUM(I40:K40) -> 0 | R40: =SUM(L40:N40) -> 0 | S40: =SUM(C40:N40) -> 430
...

Sheet NPC
A1: Conta | B1: Descrição | C1: Janeiro | D1: Fevereiro | E1: Março | F1: Abril | G1: Maio | H1: Junho | I1: Julho | J1: Agosto | K1: Setembro | L1: Outubro | M1: Novembro | N1: Dezembro | O1: 1TRI 25 | P1: 2TRI 25 | Q1: 3TRI 25 | R1: 4TRI 25 | S1: Acumulado | T1: Orçado Planejamento | U1: Diferença | V1: Orçado Unimed | W1: Diferença
A2: (+) 010 | B2: Receita Bruta Operacional | C2: 1477175.9 | D2: 1588602.8 | E2: 1365786.2 | F2: 1787262.1 | G2: 1640961.8 | H2: 1787215.6 | O2: =SUM(C2:E2) -> 4431564.9 | P2: =SUM(F2:H2) -> 5215439.6 | Q2: =SUM(I2:K2) -> 0 | R2: =SUM(L2:N2) -> 0 | S2: =SUM(C2:N2) -> 9647004.5 | T2: 8682000 | U2: =S2-T2 -> 965004.49 | V2: 8682000 | W2: =S2-V2 -> 965004.49
A3: 010.01 | B3: Faturamento Prod. Merc. e Serviços | C3: 1477175.9 | D3: 1588602.8 | E3: 1365786.2 | F3: 1787262.1 | G3: 1640961.8 | H3: 1787215.6 | O3: =SUM(C3:E3) -> 4431564.9 | P3: =SUM(F3:H3) -> 5215439.6 | Q3: =SUM(I3:K3) -> 0 | R3: =SUM(L3:N3) -> 0 | S3: =SUM(C3:N3) -> 9647004.5
A4: 010.01.03 | B4: Vendas de Serviços | C4: 1471175.9 | D4: 1585602.8 | E4: 1362786.2 | F4: 1787262.1 | G4: 1640961.8 | H4: 1787215.6 | O4: =SUM(C4:E4) -> 4419564.9 | P4: =SUM(F4:H4) -> 5215439.6 | Q4: =SUM(I4:K4) -> 0 | R4: =SUM(L4:N4) -> 0 | S4: =SUM(C4:N4) -> 9635004.5
A5: 3.01.01.01.01.0006 | B5: Receita da Prestação de Serviços - Mercado Interno | C5: 1471175.9 | D5: 1585602.8 | E5: 1362786.2 | F5: 1787262.1 | G5: 1640961.8 | H5: 1787215.6 | O5: =SUM(C5:E5) -> 4419564.9 | P5: =SUM(F5:H5) -> 5215439.6 | Q5: =SUM(I5:K5) -> 0 | R5: =SUM(L5:N5) -> 0 | S5: =SUM(C5:N5) -> 9635004.5
A6: 010.01.06 | B6: Locação de Bens Móveis e Imóveis | C6: 6000 | D6: 3000 | E6: 3000 | O6: =SUM(C6:E6) -> 12000 | P6: =SUM(F6:H6) -> 0 | Q6: =SUM(I6:K6) -> 0 | R6: =SUM(L6:N6) -> 0 | S6: =SUM(C6:N6) -> 12000
A7: 3.01.01.01.01.0008 | B7: Receita de Locação de Bens Móveis e Imóveis | C7: 6000 | D7: 3000 | E7: 3000 | O7: =SUM(C7:E7) -> 12000 | P7: =SUM(F7:H7) -> 0 | Q7: =SUM(I7:K7) -> 0 | R7: =SUM(L7:N7) -> 0 | S7: =SUM(C7:N7) -> 12000
A8: (-) 020 | B8: Deduções da Receita | C8: 97833.22 | D8: 105442.54 | E8: 90625.19 | F8: 118835.87 | G8: 109123.99 | H8: 118849.76 | O8: =SUM(C8:E8) -> 293900.95 | P8: =SUM(F8:H8) -> 346809.62 | Q8: =SUM(I8:K8) -> 0 | R8: =SUM(L8:N8) -> 0 | S8: =SUM(C8:N8) -> 640710.57 | T8: 557500 | U8: =S8-T8 -> 83210.57
A9: 020.01 | B9: Impostos Faturados | C9: 97833.22 | D9: 105442.54 | E9: 90625.19 | O9: =SUM(C9:E9) -> 293900.95 | P9: =SUM(F9:H9) -> 0 | Q9: =SUM(I9:K9) -> 0 | R9: =SUM(L9:N9) -> 0 | S9: =SUM(C9:N9) -> 293900.95
A10: 020.01.02 | B10: ISS | C10: 44135.3 | D10: 47568.04 | E10: 40883.49 | F10: 53610.16 | G10: 49228.88 | H10: 53616.39 | O10: =SUM(C10:E10) -> 132586.83 | P10: =SUM(F10:H10) -> 156455.43 | Q10: =SUM(I10:K10) -> 0 | R10: =SUM(L10:N10) -> 0 | S10: =SUM(C10:N10) -> 289042.26
A11: 3.01.01.01.03.0005 | B11: ISS | C11: 44135.3 | D11: 47568.04 | E11: 40883.49 | O11: =SUM(C11:E11) -> 132586.83 | P11: =SUM(F11:H11) -> 0 | Q11: =SUM(I11:K11) -> 0 | R11: =SUM(L11:N11) -> 0 | S11: =SUM(C11:N11) -> 132586.83
A12: 020.01.03 | B12: COFINS | C12: 44135.28 | D12: 47568.08 | E12: 40883.59 | F12: 53610.17 | G12: 49228.86 | H12: 53616.47 | O12: =SUM(C12:E12) -> 132586.95 | P12: =SUM(F12:H12) -> 156455.5 | Q12: =SUM(I12:K12) -> 0 | R12: =SUM(L12:N12) -> 0 | S12: =SUM(C12:N12) -> 289042.45
A13: 3.01.01.01.03.0003 | B13: COFINS | C13: 44135.28 | D13: 47568.08 | E13: 40883.59 | O13: =SUM(C13:E13) -> 132586.95 | P13: =SUM(F13:H13) -> 0 | Q13: =SUM(I13:K13) -> 0 | R13: =SUM(L13:N13) -> 0 | S13: =SUM(C13:N13) -> 132586.95
A14: 020.01.04 | B14: PIS | C14: 9562.64 | D14: 10306.42 | E14: 8858.11 | F14: 11615.54 | G14: 10666.25 | H14: 11616.9 | O14: =SUM(C14:E14) -> 28727.17 | P14: =SUM(F14:H14) -> 33898.69 | Q14: =SUM(I14:K14) -> 0 | R14: =SUM(L14:N14) -> 0 | S14: =SUM(C14:N14) -> 62625.86
A15: 3.01.01.01.03.0004 | B15: PIS/PASEP | C15: 9562.64 | D15: 10306.42 | E15: 8858.11 | O15: =SUM(C15:E15) -> 28727.17 | P15: =SUM(F15:H15) -> 0 | Q15: =SUM(I15:K15) -> 0 | R15: =SUM(L15:N15) -> 0 | S15: =SUM(C15:N15) -> 28727.17
A16: (=) 030 | B16: Receita Líquida | C16: 1379342.7 | D16: 1483160.2 | E16: 1275161 | F16: 1668426.2 | G16: 1531837.9 | H16: 1668365.9 | O16: =SUM(C16:E16) -> 4137664 | P16: =SUM(F16:H16) -> 4868630 | Q16: =SUM(I16:K16) -> 0 | R16: =SUM(L16:N16) -> 0 | S16: =SUM(C16:N16) -> 9006293.9 | T16: 8104500 | U16: =S16-T16 -> 901793.92
A17: (-) 040 | B17: Custo Mercad./Serv./Produtos Vendidos | C17: 670896.37 | D17: 550631.43 | E17: 659749.75 | F17: 662933.9 | G17: 572212.66 | H17: 608013.49 | O17: =SUM(C17:E17) -> 1881277.6 | P17: =SUM(F17:H17) -> 1843160.1 | Q17: =SUM(I17:K17) -> 0 | R17: =SUM(L17:N17) -> 0 | S17: =SUM(C17:N17) -> 3724437.6
A18: 040.03 | B18: Custo dos Serviços Prestados | C18: 670896.37 | D18: 550631.43 | E18: 659749.75 | O18: =SUM(C18:E18) -> 1881277.6 | P18: =SUM(F18:H18) -> 0 | Q18: =SUM(I18:K18) -> 0 | R18: =SUM(L18:N18) -> 0 | S18: =SUM(C18:N18) -> 1881277.6
A19: 3.01.01.03.06 | B19: Custo dos Serviços Produzidos | C19: 670896.37 | D19: 550631.43 | E19: 659749.75 | O19: =SUM(C19:E19) -> 1881277.6 | P19: =SUM(F19:H19) -> 0 | Q19: =SUM(I19:K19) -> 0 | R19: =SUM(L19:N19) -> 0 | S19: =SUM(C19:N19) -> 1881277.6
A20: 3.01.01.03.06.0008 | B20: Serviços Prestados Pessoa Jurídica | C20: 297917.8 | D20: 252772.9 | E20: 263222.53 | O20: =SUM(C20:E20) -> 813913.23 | P20: =SUM(F20:H20) -> 0 | Q20: =SUM(I20:K20) -> 0 | R20: =SUM(L20:N20) -> 0 | S20: =SUM(C20:N20) -> 813913.23
A21: 3.01.01.03.06.0011 | B21: INSS - Previdência Social | C21: 88026.4 | D21: 65873.66 | E21: 63210.84 | O21: =SUM(C21:E21) -> 217110.9 | P21: =SUM(F21:H21) -> 0 | Q21: =SUM(I21:K21) -> 0 | R21: =SUM(L21:N21) -> 0 | S21: =SUM(C21:N21) -> 217110.9
A22: 3.01.01.03.06.0012 | B22: FGTS | C22: 22923.83 | D22: 27467.39 | E22: 19568.04 | O22: =SUM(C22:E22) -> 69959.26 | P22: =SUM(F22:H22) -> 0 | Q22: =SUM(I22:K22) -> 0 | R22: =SUM(L22:N22) -> 0 | S22: =SUM(C22:N22) -> 69959.26
A23: 3.01.01.03.06.0014 | B23: Alimentação do Trabalhador | C23: 13750 | D23: 13482 | E23: 65259.45 | O23: =SUM(C23:E23) -> 92491.45 | P23: =SUM(F23:H23) -> 0 | Q23: =SUM(I23:K23) -> 0 | R23: =SUM(L23:N23) -> 0 | S23: =SUM(C23:N23) -> 92491.45
A24: 3.01.01.03.06.0040 | B24: Ordenados, Salários e Gratificações | C24: 164865.21 | D24: 127902.66 | E24: 172050.49 | O24: =SUM(C24:E24) -> 464818.36 | P24: =SUM(F24:H24) -> 0 | Q24: =SUM(I24:K24) -> 0 | R24: =SUM(L24:N24) -> 0 | S24: =SUM(C24:N24) -> 464818.36
A25: 3.01.01.03.06.0041 | B25: Férias | C25: 0 | D25: 0 | E25: 29157.27 | O25: =SUM(C25:E25) -> 29157.27 | P25: =SUM(F25:H25) -> 0 | Q25: =SUM(I25:K25) -> 0 | R25: =SUM(L25:N25) -> 0 | S25: =SUM(C25:N25) -> 29157.27
A26: 3.01.01.03.06.0042 | B26: Décimo Terceiro Salário | C26: 0 | D26: 0 | E26: 19601.83 | O26: =SUM(C26:E26) -> 19601.83 | P26: =SUM(F26:H26) -> 0 | Q26: =SUM(I26:K26) -> 0 | R26: =SUM(L26:N26) -> 0 | S26: =SUM(C26:N26) -> 19601.83
A27: 3.01.01.03.06.0043 | B27: Outros Gastos com Pessoal Ligado à Produção de Serviços | C27: 53281.25 | D27: 26995.44 | E27: 9267 | O27: =SUM(C27:E27) -> 89543.69 | P27: =SUM(F27:H27) -> 0 | Q27: =SUM(I27:K27) -> 0 | R27: =SUM(L27:N27) -> 0 | S27: =SUM(C27:N27) -> 89543.69
A28: 3.01.01.03.06.0045 | B28: Vale Transporte | C28: 1337.25 | D28: 868.1 | E28: -1260.57 | O28: =SUM(C28:E28) -> 944.78 | P28: =SUM(F28:H28) -> 0 | Q28: =SUM(I28:K28) -> 0 | R28: =SUM(L28:N28) -> 0 | S28: =SUM(C28:N28) -> 944.78
A29: 3.01.01.03.06.0047 | B29: Assistência Médica e Odontológica | C29: 5113.23 | D29: 12463.33 | E29: 4355.24 | O29: =SUM(C29:E29) -> 21931.8 | P29: =SUM(F29:H29) -> 0 | Q29: =SUM(I29:K29) -> 0 | R29: =SUM(L29:N29) -> 0 | S29: =SUM(C29:N29) -> 21931.8
A30: 3.01.01.03.06.0048 | B30: Rescisão de Contrato de Trabalho | C30: 23681.4 | D30: 22805.95 | E30: 15330.41 | O30: =SUM(C30:E30) -> 61817.76 | P30: =SUM(F30:H30) -> 0 | Q30: =SUM(I30:K30) -> 0 | R30: =SUM(L30:N30) -> 0 | S30: =SUM(C30:N30) -> 61817.76
A31: (=) 060 | B31: Lucro Bruto | C31: 708446.32 | D31: 932528.82 | E31: 615411.27 | F31: 1005492.3 | G31: 959625.19 | H31: 1060352.4 | O31: =SUM(C31:E31) -> 2256386.4 | P31: =SUM(F31:H31) -> 3025469.9 | Q31: =SUM(I31:K31) -> 0 | R31: =SUM(L31:N31) -> 0 | S31: =SUM(C31:N31) -> 5281856.3 | T31: 4706000 | U31: =S31-T31 -> 575856.32
A32: (-) 070 | B32: Despesas Operacionais | C32: 539659.25 | D32: 824192.58 | E32: 574253.27 | F32: 501883.86 | G32: 544990.72 | H32: 636234.54 | O32: =SUM(C32:E32) -> 1938105.1 | P32: =SUM(F32:H32) -> 1683109.1 | Q32: =SUM(I32:K32) -> 0 | R32: =SUM(L32:N32) -> 0 | S32: =SUM(C32:N32) -> 3621214.2
A33: 070.01 | B33: Despesas Administrativas | C33: 378622.09 | D33: 641868.66 | E33: 416957.3 | O33: =SUM(C33:E33) -> 1437448.1 | P33: =SUM(F33:H33) -> 0 | Q33: =SUM(I33:K33) -> 0 | R33: =SUM(L33:N33) -> 0 | S33: =SUM(C33:N33) -> 1437448.1
A34: 3.01.01.07.01 | B34: Despesas Operacionais das Atividades em Geral | C34: 304789.01 | D34: 614109.22 | E34: 400240.46 | O34: =SUM(C34:E34) -> 1319138.7 | P34: =SUM(F34:H34) -> 0 | Q34: =SUM(I34:K34) -> 0 | R34: =SUM(L34:N34) -> 0 | S34: =SUM(C34:N34) -> 1319138.7
A35: 3.01.01.07.01.0003 | B35: Ordenados, Salários, Gratif e Outras Remuner a Empregados | C35: 108353.66 | D35: 106723.65 | E35: 66104.57 | O35: =SUM(C35:E35) -> 281181.88 | P35: =SUM(F35:H35) -> 0 | Q35: =SUM(I35:K35) -> 0 | R35: =SUM(L35:N35) -> 0 | S35: =SUM(C35:N35) -> 281181.88
A36: 3.01.01.07.01.0009 | B36: Serviços Prestados Pessoa Jurídica | C36: 88794.54 | D36: 405733.11 | E36: 263222.53 | O36: =SUM(C36:E36) -> 757750.18 | P36: =SUM(F36:H36) -> 0 | Q36: =SUM(I36:K36) -> 0 | R36: =SUM(L36:N36) -> 0 | S36: =SUM(C36:N36) -> 757750.18
A37: 3.01.01.07.01.0024 | B37: Aluguéis | C37: 66215.21 | D37: 64715.21 | E37: 64715.21 | O37: =SUM(C37:E37) -> 195645.63 | P37: =SUM(F37:H37) -> 0 | Q37: =SUM(I37:K37) -> 0 | R37: =SUM(L37:N37) -> 0 | S37: =SUM(C37:N37) -> 195645.63
A38: 3.01.01.07.01.0029 | B38: Multas | C38: 0 | D38: 106.3 | E38: 0 | O38: =SUM(C38:E38) -> 106.3 | P38: =SUM(F38:H38) -> 0 | Q38: =SUM(I38:K38) -> 0 | R38: =SUM(L38:N38) -> 0 | S38: =SUM(C38:N38) -> 106.3
A39: 3.01.01.07.01.0030 | B39: Encargos de Depreciação e Amortização | C39: 3152.09 | D39: 3440.66 | E39: 3440.66 | O39: =SUM(C39:E39) -> 10033.41 | P39: =SUM(F39:H39) -> 0 | Q39: =SUM(I39:K39) -> 0 | R39: =SUM(L39:N39) -> 0 | S39: =SUM(C39:N39) -> 10033.41
A40: 3.01.01.07.01.0042 | B40: Outras Despesas Operacionais | C40: 0 | D40: 0 | E40: 430 | O40: =SUM(C40:E40) -> 430 | P40: =SUM(F40:H40) -> 0 | Q40: =SUM(I40:K40) -> 0 | R40: =SUM(L40:N40) -> 0 | S40: =SUM(C40:N40) -> 430
...

Sheet Indicadores Planilhas
A1: NPC
A3: DRE | B3: 1S 25 | C3: 1S 25 Orçado | D3: Δ vs. Orçado | G3: QUADRO I – RESULTADO SINTÉTICO | H3: REAL 2025 | I3: ORÇ 2025 | J3: DIF. ORÇ.
A4: Receita Bruta | B4: =NPC!S2 -> 9647004.5 | C4: =I4 -> 10129000 | D4: =B4-C4 -> -481995.51 | G4: Receita Bruta | H4: 11547186 | I4: 10129000 | J4: =H4-I4 -> 1418186
A5: (-) Impostos Incidentes | B5: =NPC!S8 -> 640710.57 | C5: =I5 -> 673750 | D5: =B5-C5 -> -33039.43 | G5: Impostos e Deduções Receitas | H5: 768124 | I5: 673750 | J5: =H5-I5 -> 94374
A6: Receita Líquida | B6: =(B4-B5) -> 9006293.9 | C6: =(C4-C5) -> 9455250 | D6: =B6-C6 -> -448956.08 | G6: Receita Liquida | H6: 10779062 | I6: 9455250 | J6: =H6-I6 -> 1323812
A7: Custo | B7: =NPC!S17 -> 3724437.6 | C7: =I7 -> 4638667 | D7: =B7-C7 -> -914229.4 | G7: Custos Serviços | H7: 4304076 | I7: 4638667 | J7: =H7-I7 -> -334591
A8: Despesas Operacionais | B8: =NPC!S32 -> 3621214.2 | C8: =I9 -> 3007083 | D8: =B8-C8 -> 614131.22 | G8: Lucro Bruto | H8: 6474986 | I8: =I6-I7 -> 4816583 | J8: =H8-I8 -> 1658403
A9: Lucro Operacional | B9: =B6-B7-B8 -> 1660642.1 | C9: =C6-C7-C8 -> 1809500 | D9: =B9-C9 -> -148857.9 | G9: Custos/Despesas operacionais | H9: 3621214 | I9: 3007083 | J9: =H9-I9 -> 614131
A10: Outras despesas | B10: 0 | C10: 0 | D10: =B10-C10 -> 0 | G10: Res. Antes das Participações e Contrib. | H10: 2900957 | I10: 1821903 | J10: =H10-I10 -> 1079054
A11: Resultado Financeiro | B11: =NPC!S73 -> 51539.05 | C11: 12403 | D11: =B11-C11 -> 39136.05 | G11: Amortização Empréstimo | H11: 0 | I11: 0 | J11: =H11-I11 -> 0
A12: Lucro antes de impostos | B12: =B9+B11+B10 -> 1712181.1 | C12: =C9+C11+C10 -> 1821903 | D12: =B12-C12 -> -109721.85 | G12: Impostos (CS+IR) | H12: 1035581 | I12: 1185274 | J12: =H12-I12 -> -149693
A13: Provisão de Impostos | B13: =SUM(NPC!S67:S68) -> 1224006.8 | C13: =I12 -> 1185274 | D13: =B13-C13 -> 38732.77 | G13: Lucro Líquido | H13: 1488870 | I13: 636629 | J13: =H13-I13 -> 852241
A14: Resultado Líquido | B14: =NPC!S86 -> 1083483.3 | C14: =C4-C7-C8-C13 -> 1297976 | D14: =B14-C14 -> -214492.67
A15: Margem Líquida | B15: ='Indicadores Financeiro'!E5 -> 0.12030291 | C15: =C14/C6 -> 0.13727569 | D15: =B15-C15 -> -0.016972787 | G15: INDICADORES | H15: ORÇADO | I15: REALIZADO 2025 | J15: VARIAÇÃO (vs. Orçado)
A16: Margem de Lucro | B16: ='Indicadores Financeiro'!E5 -> 0.12030291 | C16: ='Indicadores Financeiro'!F5 -> 0.19137516 | D16: =B16-C16 -> -0.071072256
A17: Indice de Eficiência | B17: ='Indicadores Financeiro'!E6 -> 0.40207595 | C17: ='Indicadores Financeiro'!F6 -> 0.31803316 | D17: =B17-C17 -> 0.084042798 | G17: RECEITA BRUTA | H17: =I4 -> 10129000 | I17: =H4 -> 11547186 | J17: =I17-H17 -> 1418186
A18: Ebitda | B18: ='Indicadores Financeiro'!E8 -> 2359029.1 | C18: ='Indicadores Financeiro'!F8 -> 2495653 | D18: =B18-C18 -> -136623.85 | G18: MARGEM DE LUCRO | H18: 0.191 | I18: 0.14 | J18: =I18-H18 -> -0.051
A19: Mg Ebitda | B19: ='Indicadores Financeiro'!E9 -> 0.26193118 | C19: ='Indicadores Financeiro'!F9 -> 0.26394363 | D19: =B19-C19 -> -0.0020124541 | G19: INDICE DE EFICIÊNCIA | H19: 0.318 | I19: 0.39 | J19: =I19-H19 -> 0.072
G20: LUCRO LIQUIDO | H20: 0.137 | I20: 1488870 | J20: =I20-H20 -> 1488869.9
A21: DRE | B21: YTD 25 | C21: YTD 25 Orçado | D21: Δ vs. Orçado | G21: EBITDA | H21: =C18 -> 2495653 | I21: 719662 | J21: =I21-H21 -> -1775991
A22: Receita Bruta | B22: =SUM([1]NPC!#REF!) -> #ERROR! | C22: ='[2]DRE NPC (2)'!$P$4+'[2]DRE NPC (2)'!$Q$4 -> #REF! | D22: =B22-C22 -> #ERROR! | G22: MG EBITDA | H22: =C19 -> 0.26394363 | I22: 0.07 | J22: =H22-I22 -> 0.19394363
A23: (-) Impostos Incidentes | B23: =-SUM([1]NPC!#REF!) -> #ERROR! | C23: =-'[2]DRE NPC (2)'!$P$5-'[2]DRE NPC (2)'!$Q$5 -> #REF! | D23: =B23-C23 -> #ERROR!
A24: Receita Líquida | B24: =SUM(B22:B23) -> #ERROR! | C24: =SUM(C22:C23) -> #REF! | D24: =B24-C24 -> #ERROR!
A25: Custo | B25: =-SUM([1]NPC!#REF!) -> #ERROR! | C25: =-'[2]DRE NPC (2)'!$P$7-'[2]DRE NPC (2)'!$Q$7 -> #REF! | D25: =B25-C25 -> #ERROR!
A26: Despesas Operacionais | B26: =-SUM([1]NPC!#REF!) -> #ERROR! | C26: =-'[2]DRE NPC (2)'!$P$8-'[2]DRE NPC (2)'!$Q$8 -> #REF! | D26: =B26-C26 -> #ERROR!
A27: Lucro Operacional | B27: =B24+B25+B26 -> #ERROR! | C27: =C24+C25+C26 -> #REF! | D27: =B27-C27 -> #ERROR!
A28: Outras despesas | B28: =[1]Corretora!N15+[1]Corretora!N16+[1]Corretora!N17 -> #ERROR! | C28: 0 | D28: =B28-C28 -> #ERROR!
A29: Resultado Financeiro | B29: =SUM([1]NPC!#REF!) -> #ERROR! | C29: ='[2]DRE NPC (2)'!$P$10+'[2]DRE NPC (2)'!$Q$10 -> #REF! | D29: =B29-C29 -> #ERROR!
A30: Lucro antes de impostos | B30: =B27+B29+B28 -> #ERROR! | C30: =C27+C29+C28 -> #REF! | D30: =B30-C30 -> #ERROR!
A31: Provisão de Impostos | B31: =-SUM([1]NPC!#REF!) -> #ERROR! | C31: =-'[2]DRE NPC (2)'!$P$12-+'[2]DRE NPC (2)'!$Q$12 -> #REF! | D31: =B31-C31 -> #ERROR! | I31: -2025 | J31: (vs. Orçado)
A32: Lucro Líquido | B32: =B30+B31 -> #ERROR! | C32: =C30+C31 -> #REF! | D32: =B32-C32 -> #ERROR! | G32: RECEITA BRUTA | H32: =C22 -> #REF! | I32: =B22 -> #ERROR! | J32: =I32-H32 -> #ERROR!
A33: Margem Líquida | B33: =B32/B24 -> #ERROR! | C33: =C32/C24 -> #REF! | D33: =B33-C33 -> #ERROR! | G33: MARGEM DE LUCRO | H33: =C33 -> #REF! | I33: =B33 -> #ERROR! | J33: =I33-H33 -> #ERROR!
A34: Margem de Lucro | B34: =B27/B24 -> #ERROR! | C34: =C27/C24 -> #REF! | D34: =B34-C34 -> #ERROR! | G34: INDICE DE EFICIÊNCIA | H34: =C35 -> #REF! | I34: =B35 -> #ERROR! | J34: =I34-H34 -> #ERROR!
A35: Indice de Eficiência | B35: =SUM(B28+B26)/B24 -> #ERROR! | C35: =SUM(C28+C26)/C24 -> #REF! | D35: =B35-C35 -> #ERROR! | G35: LUCRO LIQUIDO | H35: =C32 -> #REF! | I35: =B32 -> #ERROR! | J35: =I35-H35 -> #ERROR!
A36: Ebitda | B36: =B32-B31-B29 -> #ERROR! | C36: =C32-C31-C29 -> #REF! | D36: =B36-C36 -> #ERROR! | G36: EBITDA | H36: =C36 -> #REF! | I36: =B36 -> #ERROR! | J36: =I36-H36 -> #ERROR!
A37: Mg Ebitda | B37: =B36/B24 -> #ERROR! | C37: =C36/C24 -> #REF! | D37: =B37-C37 -> #ERROR! | G37: MG EBITDA | H37: =C37 -> #REF! | I37: =B37 -> #ERROR! | J37: =I37-H37 -> #ERROR!

Sheet Indicadores Financeiro
A1: Indicadores | B1: Formulas | D1: Indicadores | E1: Valores | F1: Orçado | G1: Observação
A2: RECEITA | B2: ACUMULADO TRIMESTRE E ANO (GRAFICO DE LINHA) | C2: Grafico de linha | D2: RECEITA | E2: =NPC!S2 -> 9647004.5 | F2: ='Indicadores Planilhas'!C4 -> 10129000 | H2: Bater todas as informações com observações
A3: RECEITA OUTROS NEGÓCIOS | B3: Soma de Autismo Club e Toyt (Sem resultado operacional) Aporte | D3: RECEITA OUTROS NEGÓCIOS | E3: 0 | F3: 0 | G3: Aporte de capital
A4: MARGEM DE BRUTA | B4: Lucro bruto/receita liquida | D4: MARGEM DE BRUTA | E4: =NPC!S91 -> 0.5864628
A5: MARGEM LUCRO | B5: lucro liquido/receita liquida | D5: MARGEM LUCRO | E5: =NPC!S87 -> 0.12030291 | F5: ='Indicadores Planilhas'!C9/'Indicadores Planilhas'!C6 -> 0.19137516
A6: INDICE DE EFICIÊNCIA | B6: Total de despesas/receitas líquidas | D6: INDICE DE EFICIÊNCIA | E6: =NPC!S90 -> 0.40207595 | F6: ='Indicadores Planilhas'!C8/'Indicadores Planilhas'!C6 -> 0.31803316 | H6: Rever despesas operacionais
A7: LUCRO LÍQUIDO | B7: lucro líquido | D7: LUCRO LÍQUIDO | E7: =NPC!S86 -> 1083483.3
A8: EBITIDA | B8: lucro liquido-IRPJ e CSLL- depreciação-resultado financeiro | D8: EBITIDA | E8: =NPC!S88 -> 2359029.1 | F8: ='Indicadores Planilhas'!C14+'Indicadores Planilhas'!C13+'Indicadores Planilhas'!C11 -> 2495653
A9: MARGEM EBITIDA | B9: EBITIDA/Receita liquida | D9: MARGEM EBITIDA | E9: =NPC!S89 -> 0.26193118 | F9: =F8/'Indicadores Planilhas'!C6 -> 0.26394363
A10: QUANTIDADE DE PACIENTES | B10: Ismael | D10: QUANTIDADE DE PACIENTES | E10: ='OKRs Consolidados'!N50 -> Consolidação | H10: 1787215.6 | I10: =H10/E10 -> #VALUE!
A11: QUANTIDADE DE NOVOS PACIENTES | B11: Ismael | D11: QUANTIDADE DE NOVOS PACIENTES | E11: 273
A12: TAXA DE OCUPAÇÃO | B12: Ismael | D12: TAXA DE OCUPAÇÃO | E12: =100%-(4%+4%+3%+4%+6%+2%+4%+9%+0%+1%+2%+17%+13%+14%+27%+4%)/16 -> 0.92875 | G12: Calculo com base em horarios livre
A13: TICKET MÉDIO POR CLIENTE | B13: Receita gerada/Quantidade (Ismael) | C13: Grafico de linha | D13: TICKET MÉDIO POR CLIENTE | E13: =E2/E10 -> #VALUE!
A14: % FATURAMENTO UNIMED | B14: Quanto a Unimed representa sobre o faturamento total | D14: % FATURAMENTO UNIMED | E14: 0.93
A15: NPS | B15: Ismael | D15: NPS | E15: =(52.1+82.1+92.1)/3 -> 75.433333
A16: ROIC | B16: noplat (LAIR/pelo número de meses já consolidados * 2)/capital investido | D16: ROIC | E16: =(NPC!S84)/B24 -> 0.93996557
A17: ENDIVIDAMENTO GERAL | B17: Divida (Emprestimo) total / Total do ativo | D17: ENDIVIDAMENTO GERAL | E17: =B32/B27 -> 0.11192164
A18: ENDIVIDAMENTO COM TERCEIROS | B18: Total de capital de terceiros/Total Ativo | D18: ENDIVIDAMENTO COM TERCEIROS | E18: =B31/B27 -> 0.44010475
A19: LIQUIDEZ CORRENTE | B19: Ativo circulante / passivo circulante | D19: LIQUIDEZ CORRENTE | E19: =B25/B29 -> 7.1864007
A20: LIQUIDEZ GERAL | B20: ativo circulante + ativo RLP / total do passivo | D20: LIQUIDEZ GERAL | E20: =(B25+B26)/B29 -> 7.990431
A21: ÍNDICE DE COBERTURA DE JUROS | B21: lucro operacional / despesas com juros | D21: ÍNDICE DE COBERTURA DE JUROS | E21: =NPC!S86/NPC!S78 -> 19.370213
A22: DIVIDA LÍQUIDA/EBITIDA | B22: financiamento e emprestimos - caixa e equivalantes total / ebitida | D22: DIVIDA LÍQUIDA/EBITIDA | E22: =(B32-B34)/NPC!S88 -> -0.55419676
A24: CAPITAL SOCIAL | B24: 1915000 | C24: FORMATO
A25: ATIVO CIRCULANTE | B25: 8035764
A26: ATIVO RLP | B26: 899058.96
A27: TOTAL DO ATIVO | B27: =B25+B26 -> 8934822.9
A28: PASSIVO NÃO CIRCULANTE | B28: 566666.71 | C28: FINANCIAMENTO?
A29: PASSIVO CIRCULANTE | B29: 1118190.4
A30: TOTAL DO PASSIVO | B30: 8287813.7
A31: CAPITAL SOCIAL TERCEIROS | B31: 3932258 | C31: CS+P
A32: EMPRESTIMOS E FINANCIAMENTOS | B32: 1000000
A33: DEPRECIAÇÃO | B33: 209672.31
A34: caixa e equivalantes total | B34: 2307366.3 | C34: =B32-B34 -> -1307366.3
A35: CAPITAL INVESTIDO | B35: 2747890

Sheet OKRs Consolidados
A1: Faturamento 2025 | B1: 46047 | C1: 46078 | D1: 46106 | E1: 46137 | F1: 46167 | G1: 46198 | H1: 46228 | I1: 46259 | J1: 46290 | K1: 46320 | L1: 46351 | M1: 46381 | N1: Consolidação/2025 | P1: 2025 | S1: Descrição | T1: Janeiro | U1: Fevereiro | V1: Março | W1: Abril | X1: Maio | Y1: Junho | Z1: Julho | AA1: Agosto | AB1: Setembro | AC1: Outubro | AD1: Novembro | AE1: Dezembro | AF1: Acumulado | AH1: INDCADORES CONSOLIDADOS | AI1: FORMULA | AJ1: CÁLCULO | AK1: VALOR | AL1: HAPVIDA | AN1: Indicador | AO1: Orçado original | AP1: Otimista | AQ1: Pessimista | AR1: Δ Otim vs Orç | AS1: Δ Pes vs Orç | AT1: Δ Otim vs Pes
A2: Receita Bruta Operacional | B2: 1471176 | C2: 1585603 | D2: 1362786 | E2: 1787006 | F2: 1640962 | G2: 1787216 | H2: 1900182 | I2: 2002064 | J2: 1904134 | K2: 2035135 | L2: 2009373 | M2: 1868483 | N2: 21354119 | P2: 9634748 | S2: (+) Receita Bruta Operacional | T2: 1653906 | U2: 1741862 | V2: 1581738 | W2: 1797928 | X2: 1801493 | Y2: 1868817 | AF2: 10445742 | AH2: L-COR | AI2: ATIVO C | AJ2: 9540594 | AK2: 8.04 | AL2: 1.83 | AN2: Receita Bruta | AO2: 25,07M | AP2: 23,94M | AQ2: 22,90M | AR2: −4,5% | AS2: −8,6% | AT2: 0.046
S3: (-) Deduções da Receita | T3: 109985 | U3: 115834 | V3: 105186 | W3: 119562 | X3: 119799 | Y3: 124276 | AF3: 694642 | AI3: PASSIVO C | AJ3: 1186499 | AN3: Custos Totais | AO3: 8,00M | AP3: 8,95M | AQ3: 8,75M | AR3: 0.119 | AS3: 0.094 | AT3: 0.023
A4: Meta 2026 | B4: 46048 | C4: 46079 | D4: 46107 | E4: 46138 | F4: 46168 | G4: 46199 | H4: 46229 | I4: 46260 | J4: 46291 | K4: 46321 | L4: 46352 | M4: 46382 | N4: Consolidação/2025 | S4: (=) Receita Líquida | T4: 1543921 | U4: 1626028 | V4: 1476552 | W4: 1678366 | X4: 1681693 | Y4: 1744540 | AF4: 9751100 | AH4: DIVIDA LÍQUIDA / EBITDA | AI4: FINAN - EQ CAIXA | AJ4: -1600252 | AK4: -0.51 | AL4: 1.5 | AN4: Despesas Oper. | AO4: 8,12M | AP4: 7,36M | AQ4: 7,31M | AR4: −9,4% | AS4: −9,9% | AT4: 0.006
A5: Receita Bruta Operacional | B5: 2002000 | C5: 1978000 | D5: 2026024 | E5: 2040206 | F5: 2064689 | G5: 2081206 | H5: 2072881 | I5: 2124703 | J5: 2145950 | K5: 2171702 | L5: 2193419 | M5: 2164904 | N5: 25065684 | S5: (=) Lucro Bruto | T5: 898717 | U5: 1041630 | V5: 916622 | W5: 1067276 | X5: 1143335 | Y5: 1158821 | AF5: 6211627 | AI5: EBITDA | AJ5: 3113863 | AN5: Lucro Líquido | AO5: 5,15M | AP5: 4,47M | AQ5: 3,93M | AR5: −13,2% | AS5: −23,7% | AT5: 0.137
S6: (-) Custo dos Serviços Prestados | T6: 645204 | U6: 584398 | V6: 559930 | W6: 611089 | X6: 538358 | Y6: 585720 | AF6: 3539474 | AH6: ICJ | AI6: EBIT | AJ6: 3066934 | AK6: 5.41 | AL6: 4.04 | AN6: Margem Líquida | AO6: 0.205 | AP6: 0.186 | AQ6: 0.172 | AR6: −1,9 p.p. | AS6: −3,3 p.p. | AT6: =+1,4 p.p. -> #ERROR!
A7: Receita Operacional | B7: Jan | C7: Fev | D7: Mar | E7: Abr | F7: Mai | G7: Jun | H7: Jul | I7: Ago | J7: Set | K7: Out | L7: Nov | M7: Dez | N7: Acumulado | P7: 2025 | Q7: 2026 | S7: (-) Despesas Operacionais | T7: 529504 | U7: 497919 | V7: 501983 | W7: 506221 | X7: 500640 | Y7: 606033 | AF7: 3163940 | AI7: DESP. C/ JUROS | AJ7: 566667
A8: 2025 | B8: 1471176 | C8: 1585603 | D8: 1362786 | E8: 1787006 | F8: 1640962 | G8: 1787216 | H8: 1900182 | I8: 2002064 | J8: 1904134 | K8: 2035135 | L8: 2009373 | M8: 1868483 | N8: 21354119 | P8: 9634748 | Q8: 10445742 | S8: Res. Antes das Participações e Contrib. | T8: 837207 | U8: 541200 | V8: 425179 | W8: 506221 | X8: 120608 | Y8: 554478 | AF8: 3066934
A9: 2026 | B9: 1653906 | C9: 1741861 | D9: 1581738 | E9: 1797928 | F9: 1801493 | G9: 1868817 | N9: 8576926 | S9: Res. Antes Imp.Renda e Contrib. Social | T9: 365837 | U9: 541200 | V9: 425179 | W9: 506221 | X9: 120608 | Y9: 554478 | AF9: 3066934
S10: Resultado Líquido do Exercicio | T10: 263550 | U10: 432514 | V10: 287256 | W10: 450937 | X10: 527719 | Y10: 400191 | AF10: 2325755
A11: Receita Operacional | B11: Jan | C11: Fev | D11: Mar | E11: Abr | F11: Mai | G11: Jun | H11: Jul | I11: Ago | J11: Set | K11: Out | L11: Nov | M11: Dez | N11: Acumulado
A12: Assefaz - Ceara | B12: 3740 | C12: 1700 | D12: 1700 | E12: 5950 | F12: 6545 | G12: - | N12: 19635 | S12: Descrição | T12: Janeiro | U12: Fevereiro | V12: Março | W12: Abril | X12: Maio | Y12: Junho | Z12: Julho | AA12: Agosto | AB12: Setembro | AC12: Outubro | AD12: Novembro | AE12: Dezembro | AF12: Acumulado
A13: Camed | B13: 34935 | C13: 28495 | D13: 23375 | E13: 32045 | F13: 25755 | G13: 29920 | N13: 144605 | S13: MARGEM LIQUIDA | T13: 0.17 | U13: 0.27 | V13: 0.19 | W13: 0.27 | X13: 0.31 | Y13: 0.23 | AF13: 0.24
A14: Casembrapa | B14: 3926 | C14: 3750 | D14: 3424 | E14: 3995 | F14: 2427 | G14: 4033 | N14: 17522 | S14: EBITDA | T14: 373445 | U14: 548991 | V14: 433017 | W14: 576196 | X14: 656238 | Y14: 562389 | AF14: 3113863
A15: Fusex | B15: 55439 | C15: - | D15: 31170 | E15: 8747 | G15: 27486 | N15: 95356 | S15: Margem Ebitda | T15: 0.24 | U15: 0.34 | V15: 0.29 | W15: 0.34 | X15: 0.39 | Y15: 0.32 | AF15: 0.32
A16: Marinha | B16: 43039 | C16: - | D16: 40947 | E16: 71723 | F16: 37320 | N16: 193029 | S16: Indice de Eficiência | T16: 0.34 | U16: 0.31 | V16: 0.34 | W16: 0.3 | X16: 0.3 | Y16: 0.35 | AF16: 0.32
A17: Particular | B17: 2035 | C17: 2870 | D17: 1440 | E17: 1310 | F17: 1740 | G17: 4456 | N17: 9395 | S17: Margem Bruta | T17: 0.58 | U17: 0.64 | V17: 0.62 | W17: 0.64 | X17: 0.68 | Y17: 0.66 | AF17: 0.64
A18: Unimed Central Nacional | B18: 39900 | C18: - | D18: 1100 | E18: 1400 | F18: 1100 | G18: 1200 | N18: 43500
A19: Unimed Fesp | B19: 7638 | C19: 6524 | D19: 4772 | E19: 4237 | F19: 7626 | G19: 4406 | N19: 30797 | S19: Cenário Otimista
A20: Unimed Fortaleza | B20: 1463254 | C20: 1706327 | D20: 1473810 | E20: 1668521 | F20: 1718979 | G20: 1797315 | N20: 8030891 | S20: Descrição | T20: Janeiro | U20: Fevereiro | V20: Março | W20: Abril | X20: Maio | Y20: Junho | Z20: Julho | AA20: Agosto | AB20: Setembro | AC20: Outubro | AD20: Novembro | AE20: Dezembro | AF20: Acumulado
A21: Receita Bruta Operacional | B21: 1653906 | C21: 1741861 | D21: 1581738 | E21: 1797928 | F21: 1801493 | G21: 1868817 | N21: 8576926 | S21: (+) Receita Bruta Operacional | T21: 1653906 | U21: 1741862 | V21: 1581738 | W21: 1927000 | X21: 1995000 | Y21: 1990000 | Z21: 2031000 | AA21: 2152000 | AB21: 2233000 | AC21: 2279000 | AD21: 2250000 | AE21: 2093000 | AF21: 23927505
A22: Observações | S22: (-) Deduções da Receita | T22: 109985 | U22: 115834 | V22: 105186 | W22: 128146 | X22: 132668 | Y22: 132335 | Z22: 135062 | AA22: 143108 | AB22: 148495 | AC22: 151554 | AD22: 149625 | AE22: 139185 | AF22: 1591179
A23: Faturamento TO | N23: - | S23: (=) Receita Líquida | T23: 1543921 | U23: 1626028 | V23: 1476552 | W23: 1798855 | X23: 1862333 | Y23: 1857665 | Z23: 1895939 | AA23: 2008892 | AB23: 2084506 | AC23: 2127447 | AD23: 2100375 | AE23: 1953816 | AF23: 22336326
A24: Fatuiramento Demais Atividades | N24: - | S24: (=) Lucro Bruto | T24: 898717 | U24: 1041630 | V24: 916622 | W24: 1093704 | X24: 1132298 | Y24: 1129460 | Z24: 1152731 | AA24: 1221406 | AB24: 1267379 | AC24: 1293487 | AD24: 1277028 | AE24: 1187920 | AF24: 13612382
S25: (-) Custo dos Serviços Prestados | T25: 645204 | U25: 584398 | V25: 559930 | W25: 705151 | X25: 730034 | Y25: 728205 | Z25: 743208 | AA25: 787486 | AB25: 817126 | AC25: 833959 | AD25: 823347 | AE25: 765896 | AF25: 8723944
A26: Representividade | B26: Jan | C26: Fev | D26: Mar | E26: Abr | F26: Mai | G26: Jun | H26: Jul | I26: Ago | J26: Set | K26: Out | L26: Nov | M26: Dez | N26: Consolidação/Mês | O26: % | S26: (-) Despesas Operacionais | T26: 529504 | U26: 497919 | V26: 501983 | W26: 593622 | X26: 614570 | Y26: 613029 | Z26: 625660 | AA26: 662934 | AB26: 687887 | AC26: 702057 | AD26: 693124 | AE26: 644759 | AF26: 7367048
A27: Assefaz - Ceara | B27: 935 | C27: 425 | D27: 425 | E27: 1190 | F27: 1309 | G27: - | H27: - | I27: - | J27: - | K27: - | L27: - | M27: - | N27: 857 | O27: 0.0019 | S27: Res. Antes das Participações e Contrib. | T27: 365837 | U27: 541200 | V27: 425179 | W27: 513931 | X27: 532067 | Y27: 530733 | Z27: 541668 | AA27: 573938 | AB27: 595541 | AC27: 607809 | AD27: 600075 | AE27: 558203 | AF27: 6386180
A28: Camed | B28: 2911 | C28: 2192 | D28: 2125 | E28: 3205 | F28: 2146 | G28: 2302 | H28: - | I28: - | J28: - | K28: - | L28: - | M28: - | N28: 2480 | O28: 0.0167 | S28: Res. Antes Imp.Renda e Contrib. Social | T28: 365837 | U28: 541200 | V28: 425179 | W28: 513931 | X28: 532067 | Y28: 530733 | Z28: 541668 | AA28: 573938 | AB28: 595541 | AC28: 607809 | AD28: 600075 | AE28: 558203 | AF28: 6386180
A29: Casembrapa | B29: 1963 | C29: 1875 | D29: 1712 | E29: 1998 | F29: 1214 | G29: 2016 | H29: - | I29: - | J29: - | K29: - | L29: - | M29: - | N29: 1796 | O29: 0.0021 | S29: Resultado Líquido do Exercicio | T29: 263550 | U29: 432514 | V29: 287256 | W29: 328002 | X29: 351012 | Y29: 338725 | Z29: 345704 | AA29: 393293 | AB29: 380087 | AC29: 387917 | AD29: 382981 | AE29: 356257 | AF29: 4247298
A30: Fusex | B30: 6160 | C30: - | D30: 3463 | E30: 1749 | F30: - | G30: 9162 | H30: - | I30: - | J30: - | K30: - | L30: - | M30: - | N30: 5134 | O30: 0.0118
A31: Marinha | B31: 2152 | C31: - | D31: 2275 | E31: 3985 | F31: 1964 | G31: - | H31: - | I31: - | J31: - | K31: - | L31: - | M31: - | N31: 2594 | O31: 0.0185 | S31: Descrição | T31: Janeiro | U31: Fevereiro | V31: Março | W31: Abril | X31: Maio | Y31: Junho | Z31: Julho | AA31: Agosto | AB31: Setembro | AC31: Outubro | AD31: Novembro | AE31: Dezembro | AF31: Acumulado
A32: Particular | B32: 509 | C32: 574 | D32: 720 | E32: 437 | F32: 435 | G32: 891 | H32: - | I32: - | J32: - | K32: - | L32: - | M32: - | N32: 594 | O32: 0.0013 | S32: MARGEM LIQUIDA | T32: 0.17 | U32: 0.27 | V32: 0.19 | AF32: 0.21
A33: Unimed Central Nacional | B33: 2660 | C33: - | D33: 550 | E33: 700 | F33: 367 | G33: 300 | H33: - | I33: - | J33: - | K33: - | L33: - | M33: - | N33: 915 | O33: 0.0043 | S33: EBITDA | T33: 373445 | U33: 548991 | V33: 433017 | AF33: 1355453
A34: Unimed Fesp | B34: 2546 | C34: 2175 | D34: 2386 | E34: 2118 | F34: 2542 | G34: 2203 | H34: - | I34: - | J34: - | K34: - | L34: - | M34: - | N34: 2328 | O34: 0.0034 | S34: Margem Ebitda | T34: 0.24 | U34: 0.34 | V34: 0.29 | AF34: 0.29
A35: Unimed Fortaleza | B35: 1117 | C35: 1296 | D35: 1142 | E35: 1270 | F35: 1311 | G35: 1390 | H35: - | I35: - | J35: - | K35: - | L35: - | M35: - | N35: 1254 | O35: 0.9409 | S35: Indice de Eficiência | T35: 0.34 | U35: 0.31 | V35: 0.34 | AF35: 0.33
S36: Margem Bruta | T36: 0.58 | U36: 0.64 | V36: 0.62 | AF36: 0.61
A37: Quantidade de PAX | B37: Jan | C37: Fev | D37: Mar | E37: Abr | F37: Mai | G37: Jun | H37: Jul | I37: Ago | J37: Set | K37: Out | L37: Nov | M37: Dez | N37: Consolidação
A38: Assefaz - Ceara | B38: 4 | C38: 4 | D38: 4 | E38: 5 | F38: 5 | G38: 5 | N38: 4 | S38: Cenario Pessimista
A39: Camed | B39: 12 | C39: 13 | D39: 11 | E39: 10 | F39: 12 | G39: 13 | N39: 12 | S39: Descrição | T39: Janeiro | U39: Fevereiro | V39: Março | W39: Abril | X39: Maio | Y39: Junho | Z39: Julho | AA39: Agosto | AB39: Setembro | AC39: Outubro | AD39: Novembro | AE39: Dezembro | AF39: Acumulado
A40: Casembrapa | B40: 2 | C40: 2 | D40: 2 | E40: 2 | F40: 2 | G40: 2 | N40: 2 | S40: (+) Receita Bruta Operacional | T40: 1653906 | U40: 1741862 | V40: 1581738 | W40: 1760000 | X40: 1890000 | Y40: 1730000 | Z40: 1630000 | AA40: 1960000 | AB40: 1990000 | AC40: 2150000 | AD40: 1975000 | AE40: 1890000 | AF40: 21952505
...

Sheet Página1

Sheet Planilha4
A1: Paciente
A2: Bernardo Sales Rodrigues
A3: Diego Monte Teixeira Filho
A4: Jose Ravi Nogueira de Oliveira

Sheet Planilha3
A1: Pacientes

Sheet ORÇAMENTO 2026 (Organ)
A1: Descrição | B1: JAN | C1: FEV | D1: MAR | E1: ABR | F1: MAI | G1: JUN | H1: JUL | I1: AGO | J1: SET | K1: OUT | L1: NOV | M1: DEZ | O1: 1T | P1: 2T | Q1: 3T | R1: 4T | S1: Consolidação/2026
A2: Receita Bruta Operacional | B2: 2002000 | C2: 1978000 | D2: 2026024 | E2: 2040206 | F2: 2064689 | G2: 2081206 | H2: 2072881 | I2: 2124703 | J2: 2145950 | K2: 2171702 | L2: 2193419 | M2: 2164904 | O2: =SUM(B2:D2) -> 6006024 | P2: =SUM(E2:G2) -> 6186101 | Q2: =SUM(H2:J2) -> 6343534 | R2: =SUM(K2:M2) -> 6530025 | S2: =SUM(B2:M2) -> 25065684
A3: Justificativas | C3: Mês curto | E3: Clinica Aracati | F3: Carnaval | H3: Férias | I3: Nova Clinica | M3: Férias | O3: =SUM(B3:D3) -> 0 | P3: =SUM(E3:G3) -> 0 | Q3: =SUM(H3:J3) -> 0 | R3: =SUM(K3:M3) -> 0 | S3: =SUM(B3:M3) -> 0
A4: Deduções da Receita Bruta | B4: =B2*7% -> 140140 | C4: =C2*7% -> 138460 | D4: =D2*7% -> 141821.68 | E4: =E2*7% -> 142814.42 | F4: =F2*7% -> 144528.23 | G4: =G2*7% -> 145684.42 | H4: =H2*7% -> 145101.67 | I4: =I2*7% -> 148729.21 | ... M4: =M2*7% -> 151543.28 | O4: =SUM(B4:D4) -> 420421.68 | P4: =SUM(E4:G4) -> 433027.07 | Q4: =SUM(H4:J4) -> 444047.38 | R4: =SUM(K4:M4) -> 457101.75 | S4: =SUM(B4:M4) -> 1754597.9
A5: Receita Líquida | B5: =B2-B4 -> 1861860 | C5: =C2-C4 -> 1839540 | D5: =D2-D4 -> 1884202.3 | E5: =E2-E4 -> 1897391.6 | F5: =F2-F4 -> 1920160.8 | G5: =G2-G4 -> 1935521.6 | H5: =H2-H4 -> 1927779.3 | I5: =I2-I4 -> 1975973.8 | ... M5: =M2-M4 -> 2013360.7 | O5: =SUM(B5:D5) -> 5585602.3 | P5: =SUM(E5:G5) -> 5753073.9 | Q5: =SUM(H5:J5) -> 5899486.6 | R5: =SUM(K5:M5) -> 6072923.2 | S5: =SUM(B5:M5) -> 23311086
A6: Custo dos Bens e Serviços Vendidos | B6: =B5*38% -> 707506.8 | C6: =C5*38% -> 699025.2 | D6: =D5*38% -> 715996.88 | E6: =E5*38% -> 721008.8 | F6: =F5*38% -> 729661.09 | G6: =G5*38% -> 735498.2 | H6: =H5*38% -> 732556.15 | I6: =I5*38% -> 750870.04 | ... M6: =M5*38% -> 765077.07 | O6: =SUM(B6:D6) -> 2122528.9 | P6: =SUM(E6:G6) -> 2186168.1 | Q6: =SUM(H6:J6) -> 2241804.9 | R6: =SUM(K6:M6) -> 2307710.8 | S6: =SUM(B6:M6) -> 8858212.7
A7: Lucro Bruto | B7: =B5-B6 -> 1154353.2 | C7: =C5-C6 -> 1140514.8 | D7: =D5-D6 -> 1168205.4 | E7: =E5-E6 -> 1176382.8 | F7: =F5-F6 -> 1190499.7 | G7: =G5-G6 -> 1200023.4 | H7: =H5-H6 -> 1195223.2 | I7: =I5-I6 -> 1225103.8 | ... M7: =M5-M6 -> 1248283.6 | O7: =SUM(B7:D7) -> 3463073.4 | P7: =SUM(E7:G7) -> 3566905.8 | Q7: =SUM(H7:J7) -> 3657681.7 | R7: =SUM(K7:M7) -> 3765212.4 | S7: =SUM(B7:M7) -> 14452873
A8: Despesas Operacionais | B8: =B5*32% -> 595795.2 | C8: =C5*32% -> 588652.8 | D8: =D5*32% -> 602944.74 | E8: =E5*32% -> 607165.31 | F8: =F5*32% -> 614451.45 | G8: =G5*32% -> 619366.91 | H8: =H5*32% -> 616889.39 | I8: =I5*32% -> 632311.61 | ... M8: =M5*32% -> 644275.43 | O8: =SUM(B8:D8) -> 1787392.7 | P8: =SUM(E8:G8) -> 1840983.7 | Q8: =SUM(H8:J8) -> 1887835.7 | R8: =SUM(K8:M8) -> 1943335.4 | S8: =SUM(B8:M8) -> 7459547.6
A9: Provisão para CSLL e IRPJ | B9: =B2*7% -> 140140 | C9: =C2*7% -> 138460 | D9: =D2*7% -> 141821.68 | E9: =E2*7% -> 142814.42 | F9: =F2*7% -> 144528.23 | G9: =G2*7% -> 145684.42 | H9: =H2*7% -> 145101.67 | I9: =I2*7% -> 148729.21 | ... M9: =M2*7% -> 151543.28 | O9: =SUM(B9:D9) -> 420421.68 | P9: =SUM(E9:G9) -> 433027.07 | Q9: =SUM(H9:J9) -> 444047.38 | R9: =SUM(K9:M9) -> 457101.75 | S9: =SUM(B9:M9) -> 1754597.9
A10: Res. Antes das Participações e Contrib. | B10: =B7-B8 -> 558558 | C10: =C7-C8 -> 551862 | D10: =D7-D8 -> 565260.7 | E10: =E7-E8 -> 569217.47 | F10: =F7-F8 -> 576048.23 | G10: =G7-G8 -> 580656.47 | H10: =H7-H8 -> 578333.8 | I10: =I7-I8 -> 592792.14 | ... M10: =M7-M8 -> 604008.22 | O10: =SUM(B10:D10) -> 1675680.7 | P10: =SUM(E10:G10) -> 1725922.2 | Q10: =SUM(H10:J10) -> 1769846 | R10: =SUM(K10:M10) -> 1821877 | S10: =SUM(B10:M10) -> 6993325.8
A11: Resultado Líquido do Exercicio | B11: =B10-B9 -> 418418 | C11: =C10-C9 -> 413402 | D11: =D10-D9 -> 423439.02 | E11: =E10-E9 -> 426403.05 | F11: =F10-F9 -> 431520 | G11: =G10-G9 -> 434972.05 | H11: =H10-H9 -> 433232.13 | I11: =I10-I9 -> 444062.93 | ... M11: =M10-M9 -> 452464.94 | O11: =SUM(B11:D11) -> 1255259 | P11: =SUM(E11:G11) -> 1292895.1 | Q11: =SUM(H11:J11) -> 1325798.6 | R11: =SUM(K11:M11) -> 1364775.2 | S11: =SUM(B11:M11) -> 5238728
A13: Descrição | B13: Janeiro | C13: Fevereiro | D13: Março | E13: Abril | F13: Maio | G13: Junho | H13: Julho | I13: Agosto | J13: Setembro | K13: Outubro | L13: Novembro | M13: Dezembro | O13: 1T | P13: 2T | Q13: 3T | R13: 4T | S13: Acumulado
A14: MARGEM LIQUIDA | B14: =B11/B5 -> 0.22473118 | C14: =C11/C5 -> 0.22473118 | D14: =D11/D5 -> 0.22473118 | E14: =E11/E5 -> 0.22473118 | F14: =F11/F5 -> 0.22473118 | G14: =G11/G5 -> 0.22473118 | H14: =H11/H5 -> 0.22473118 | I14: =I11/I5 -> 0.22473118 | ... M14: =M11/M5 -> 0.22473118 | O14: =SUM(B14:D14)/3 -> 0.22473118 | P14: =SUM(E14:G14)/3 -> 0.22473118 | Q14: =SUM(H14:J14)/3 -> 0.22473118 | R14: =SUM(K14:M14)/3 -> 0.22473118 | S14: =S11/S5 -> 0.22473118
A15: EBITDA | B15: =B11+B9+45000 -> 603558 | C15: =C11+C9+45000 -> 596862 | D15: =D11+D9+45000 -> 610260.7 | E15: =E11+E9+45000 -> 614217.47 | F15: =F11+F9+45000 -> 621048.23 | G15: =G11+G9+45000 -> 625656.47 | H15: =H11+H9+45000 -> 623333.8 | I15: =I11+I9+45000 -> 637792.14 | ... M15: =M11+M9+45000 -> 649008.22 | O15: =SUM(B15:D15) -> 1810680.7 | P15: =SUM(E15:G15) -> 1860922.2 | Q15: =SUM(H15:J15) -> 1904846 | R15: =SUM(K15:M15) -> 1956877 | S15: =S11+S9+(45000*12) -> 7533325.8
A16: Margem Ebitda | B16: =B15/B5 -> 0.32416938 | C16: =C15/C5 -> 0.32446264 | D16: =D15/D5 -> 0.32388279 | E16: =E15/E5 -> 0.32371677 | F16: =F15/F5 -> 0.32343554 | G16: =G15/G5 -> 0.32324955 | H16: =H15/H5 -> 0.32334292 | I16: =I15/I5 -> 0.32277358 | ... M16: =M15/M5 -> 0.32235069 | O16: =SUM(B16:D16)/3 -> 0.3241716 | P16: =SUM(C16:E16)/3 -> 0.32402073 | Q16: =SUM(D16:F16)/3 -> 0.32367836 | R16: =SUM(E16:G16)/3 -> 0.32346728 | S16: =S15/S5 -> 0.32316494
A17: Indice de Eficiência | B17: =B8/B5 -> 0.32 | C17: =C8/C5 -> 0.32 | D17: =D8/D5 -> 0.32 | E17: =E8/E5 -> 0.32 | F17: =F8/F5 -> 0.32 | G17: =G8/G5 -> 0.32 | H17: =H8/H5 -> 0.32 | I17: =I8/I5 -> 0.32 | ... M17: =M8/M5 -> 0.32 | O17: =SUM(B17:D17)/3 -> 0.32 | P17: =SUM(C17:E17)/3 -> 0.32 | Q17: =SUM(D17:F17)/3 -> 0.32 | R17: =SUM(E17:G17)/3 -> 0.32 | S17: =S8/S5 -> 0.32
A18: Margem Bruta | B18: =B7/B5 -> 0.62 | C18: =C7/C5 -> 0.62 | D18: =D7/D5 -> 0.62 | E18: =E7/E5 -> 0.62 | F18: =F7/F5 -> 0.62 | G18: =G7/G5 -> 0.62 | H18: =H7/H5 -> 0.62 | I18: =I7/I5 -> 0.62 | ... M18: =M7/M5 -> 0.62 | O18: =SUM(B18:D18)/3 -> 0.62 | P18: =SUM(C18:E18)/3 -> 0.62 | Q18: =SUM(D18:F18)/3 -> 0.62 | R18: =SUM(E18:G18)/3 -> 0.62 | S18: =S7/S5 -> 0.62
A20: Fluxo de Caixa | B20: 1T | C20: 2T | D20: 3T | E20: 4T | F20: Acumulado | S20: =S6+S8 -> 16317760
A21: Lucro Líquido | B21: 1250656 | C21: 1354091 | D21: 1432965 | E21: 1500836 | F21: =SUM(B21:E21) -> 5538548 | S21: =S20/12 -> 1359813.4
A22: (+) Depreciação e Amortização | B22: 166954 | C22: 180761 | D22: 191291 | E22: 200351 | F22: =SUM(B22:E22) -> 739357
A23: (+/-) Variação em Contas a Receber | B23: -120000 | C23: -140000 | D23: -120000 | E23: -120000 | F23: =SUM(B23:E23) -> -500000
A24: (+/-) Variação em Fornecedores | B24: 80000 | C24: 100000 | D24: 100000 | E24: 120000 | F24: =SUM(B24:E24) -> 400000
A25: (+/-) Variação em Obrigações e Encargos | B25: 60000 | C25: 70000 | D25: 80000 | E25: 90000 | F25: =SUM(B25:E25) -> 300000
A26: Caixa Líquido das Atividades Operacionais (FCO) | B26: =SUM(B21:B25) -> 1437610 | C26: =SUM(C21:C25) -> 1564852 | D26: =SUM(D21:D25) -> 1684256 | E26: =SUM(E21:E25) -> 1791187 | F26: =SUM(B26:E26) -> 6477905
A27: (-) Investimentos em Imobilizado / Equipamentos | B27: -250000 | C27: -350000 | D27: -400000 | E27: -350000 | F27: =SUM(B27:E27) -> -1350000
A28: Caixa Líquido das Atividades de Investimento (FCI) | B28: =B27 -> -250000 | C28: =C27 -> -350000 | D28: =D27 -> -400000 | E28: =E27 -> -350000 | F28: =SUM(B28:E28) -> -1350000
A29: (-) Amortização de Empréstimos | B29: -70000 | C29: -90000 | D29: -90000 | E29: -70000 | F29: =SUM(B29:E29) -> -320000
A30: (-) Distribuição de Lucros / Pró-labore | B30: -260000 | C30: -260000 | D30: -260000 | E30: -260000 | F30: =SUM(B30:E30) -> -1040000
A31: Caixa Líquido das Atividades de Financiamento (FCF) | B31: =SUM(B29:B30) -> -330000 | C31: =SUM(C29:C30) -> -350000 | D31: =SUM(D29:D30) -> -350000 | E31: =SUM(E29:E30) -> -330000 | F31: =SUM(B31:E31) -> -1360000
A32: Variação Líquida do Caixa no Trimestre | B32: =SUM(B26,B28,B31) -> 857610 | C32: =SUM(C26,C28,C31) -> 864852 | D32: =SUM(D26,D28,D31) -> 934256 | E32: =SUM(E26,E28,E31) -> 1111187 | F32: =SUM(B32:E32) -> 3767905
A33: Caixa Inicial (01/01/2025) | B33: 1800000 | C33: =B33+B32 -> 2657610 | D33: =C33+C32 -> 3522462 | E33: =D33+D32 -> 4456718 | F33: 0
A34: Caixa Final (31/12/2025) | B34: =C33 -> 2657610 | C34: =D33 -> 3522462 | D34: =E33 -> 4456718 | E34: =F32+B33 -> 5567905 | F34: 0
A35: Aumento ou Redução de Caixa | B35: =B34-B33 -> 857610 | C35: =C34-C33 -> 864852 | D35: =D34-D33 -> 934256 | E35: =E34-E33 -> 1111187 | F35: =F34-F33 -> 0

Sheet ORÇAMENTO 2026
A1: Descrição | B1: JAN | C1: FEV | D1: MAR | E1: ABR | F1: MAI | G1: JUN | H1: JUL | I1: AGO | J1: SET | K1: OUT | L1: NOV | M1: DEZ | O1: 1T | P1: 2T | Q1: 3T | R1: 4T | S1: Consolidação
A2: Receita Bruta Operacional | B2: 2002000 | C2: 1978000 | D2: 2026024 | E2: 2040206 | F2: 2064689 | G2: 2081206 | H2: 2072881 | I2: 2124703 | J2: 2145950 | K2: 2171702 | L2: 2193419 | M2: 2164904 | O2: 6006024 | P2: 6186101 | Q2: 6343535 | R2: 6530025 | S2: 25065685
A3: Deduções da Receita Bruta | B3: 140140 | C3: 138460 | D3: 141822 | E3: 142814 | F3: 144528 | G3: 145684 | H3: 145102 | I3: 148729 | J3: 150217 | K3: 152019 | L3: 153539 | M3: 151543 | O3: 420422 | P3: 433027 | Q3: 444047 | R3: 457102 | S3: 1754598
A4: Receita Líquida | B4: 1861860 | C4: 1839540 | D4: 1884202 | E4: 1897392 | F4: 1920160 | G4: 1935522 | H4: 1927780 | I4: 1975974 | J4: 1995734 | K4: 2019683 | L4: 2039879 | M4: 2013361 | O4: 5585602 | P4: 5753074 | Q4: 5899488 | R4: 6072923 | S4: 23311087
A5: Custo dos Bens e Serviços Vendidos | B5: 661182 | C5: 637182 | D5: 649188 | E5: 652733 | F5: 658854 | G5: 662983 | H5: 667902 | I5: 673858 | J5: 679170 | K5: 685607 | L5: 691037 | M5: 683908 | O5: 1947552 | P5: 1974571 | Q5: 2020930 | R5: 2060552 | S5: 8003605
A6: Lucro Bruto | B6: 1200678 | C6: 1202358 | D6: 1235014 | E6: 1244658 | F6: 1261306 | G6: 1272538 | H6: 1259877 | I6: 1302116 | J6: 1316564 | K6: 1334075 | L6: 1348843 | M6: 1329453 | O6: 3638050 | P6: 3778503 | Q6: 3878558 | R6: 4012371 | S6: 15307483
A7: Despesas Operacionais | B7: 682874 | C7: 676674 | D7: 679674 | E7: 674574 | F7: 676274 | G7: 677674 | H7: 687174 | I7: 674274 | J7: 681274 | K7: 674474 | L7: 689274 | M7: 674174 | O7: 2039221 | P7: 2028521 | Q7: 2042721 | R7: 2037921 | S7: 8148384
A8: Provisão para CSLL e IRPJ | B8: 120120 | C8: 118680 | D8: 121561 | E8: 122412 | F8: 123881 | G8: 124872 | H8: 124373 | I8: 127482 | J8: 128757 | K8: 130302 | L8: 131605 | M8: 129894 | O8: 360361 | P8: 371166 | Q8: 380612 | R8: 391801 | S8: 1503941
A9: Res. Antes das Participações e Contrib. | B9: 467638 | C9: 481518 | D9: 511174 | E9: 525918 | F9: 540866 | G9: 550698 | H9: 528537 | I9: 583676 | J9: 591124 | K9: 615435 | L9: 615402 | M9: 611113 | O9: 1460329 | P9: 1617481 | Q9: 1703337 | R9: 1841950 | S9: 6623097
A10: Resultado Líquido do Exercicio | B10: 347518 | C10: 362838 | D10: 389612 | E10: 403505 | F10: 416985 | G10: 425825 | H10: 404164 | I10: 456194 | J10: 462367 | K10: 485133 | L10: 483797 | M10: 481218 | O10: 1099968 | P10: 1246315 | Q10: 1322724 | R10: 1450148 | S10: 5119156
A12: Descrição | B12: Janeiro | C12: Fevereiro | D12: Março | E12: Abril | F12: Maio | G12: Junho | H12: Julho | I12: Agosto | J12: Setembro | K12: Outubro | L12: Novembro | M12: Dezembro | O12: 1T | P12: 2T | Q12: 3T | R12: 4T | S12: Acumulado
A13: MARGEM LIQUIDA | B13: =B10/B4 -> 0.18665098 | C13: =C10/C4 -> 0.19724388 | D13: =D10/D4 -> 0.20677825 | E13: =E10/E4 -> 0.21266296 | F13: =F10/F4 -> 0.21716159 | G13: =G10/G4 -> 0.22000525 | H13: =H10/H4 -> 0.20965255 | I13: =I10/I4 -> 0.23087045 | ... M13: =M10/M4 -> 0.23901228 | O13: =SUM(B13:D13)/3 -> 0.19689104 | P13: =SUM(E13:G13)/3 -> 0.21660993 | Q13: =SUM(H13:J13)/3 -> 0.22406689 | R13: =SUM(K13:M13)/3 -> 0.23879476 | S13: =S10/S4 -> 0.21960177
A14: EBITDA | B14: =B10+B8+45000 -> 512638 | C14: =C10+C8+45000 -> 526518 | D14: =D10+D8+45000 -> 556173 | E14: =E10+E8+45000 -> 570917 | F14: =F10+F8+45000 -> 585866 | G14: =G10+G8+45000 -> 595697 | H14: =H10+H8+45000 -> 573537 | I14: =I10+I8+45000 -> 628676 | ... M14: =M10+M8+45000 -> 656112 | O14: =SUM(B14:D14) -> 1595329 | P14: =SUM(E14:G14) -> 1752480 | Q14: =SUM(H14:J14) -> 1838337 | R14: =SUM(K14:M14) -> 1976949 | S14: =S10+S8+(45000*12) -> 7163097
A15: Margem Ebitda | B15: =B14/B4 -> 0.27533649 | C15: =C14/C4 -> 0.28622264 | D15: =D14/D4 -> 0.29517695 | E15: =E14/E4 -> 0.30089565 | F15: =F14/F4 -> 0.30511312 | G15: =G14/G4 -> 0.30777072 | H15: =H14/H4 -> 0.29751165 | I15: =I14/I4 -> 0.31816006 | ... M15: =M14/M4 -> 0.32587897 | O15: =SUM(B15:D15)/3 -> 0.28557869 | P15: =SUM(C15:E15)/3 -> 0.29409841 | Q15: =SUM(D15:F15)/3 -> 0.30039524 | R15: =SUM(E15:G15)/3 -> 0.30459316 | S15: =S14/S4 -> 0.30728284
A16: Indice de Eficiência | B16: =B7/B4 -> 0.36676979 | C16: =C7/C4 -> 0.36784957 | D16: =D7/D4 -> 0.36072247 | E16: =E7/E4 -> 0.35552695 | F16: =F7/F4 -> 0.35219669 | G16: =G7/G4 -> 0.35012467 | H16: =H7/H4 -> 0.35645872 | I16: =I7/I4 -> 0.34123627 | ... M16: =M7/M4 -> 0.33485003 | O16: =SUM(B16:D16)/3 -> 0.36511394 | P16: =SUM(C16:E16)/3 -> 0.36136633 | Q16: =SUM(D16:F16)/3 -> 0.35614871 | R16: =SUM(E16:G16)/3 -> 0.35261611 | S16: =S7/S4 -> 0.34954972
A17: Margem Bruta | B17: =B6/B4 -> 0.64488093 | C17: =C6/C4 -> 0.65361884 | D17: =D6/D4 -> 0.65545732 | E17: =E6/E4 -> 0.65598358 | F17: =F6/F4 -> 0.65687547 | G17: =G6/G4 -> 0.65746501 | H17: =H6/H4 -> 0.65353775 | I17: =I6/I4 -> 0.65897426 | ... M17: =M6/M4 -> 0.66031526 | O17: =SUM(B17:D17)/3 -> 0.65131903 | P17: =SUM(C17:E17)/3 -> 0.65501991 | Q17: =SUM(D17:F17)/3 -> 0.65610546 | R17: =SUM(E17:G17)/3 -> 0.65677469 | S17: =S6/S4 -> 0.65666106
A19: Fluxo de Caixa | B19: 1T | C19: 2T | D19: 3T | E19: 4T | F19: Acumulado | S19: =S5+S7 -> 16151989
A20: Lucro Líquido | B20: 1099968 | C20: 1246315 | D20: 1322724 | E20: 1450148 | F20: 5119156 | H20: CAPEX | I20: Valor | S20: =S19/12 -> 1345999.1
A21: (+) Depreciação e Amortização | B21: 33946 | C21: 33946 | D21: 33946 | E21: 33946 | F21: 135784 | H21: Sul | I21: 350000
A22: (+/-) Variação em Contas a Receber | B22: -865602 | C22: -865602 | D22: -865602 | E22: -865602 | F22: -3462408 | H22: Nova Unidade | I22: 650000
A23: (+/-) Variação em Fornecedores | B23: 43306 | C23: 43306 | D23: 43306 | E23: 43306 | F23: 173224
A24: (+/-) Variação em Obrigações e Encargos | B24: 230030 | C24: 230030 | D24: 230030 | E24: 230030 | F24: 920120
A25: Caixa Líquido das Atividades Operacionais (FCO) | B25: 541648 | C25: 687995 | D25: 764404 | E25: 891828 | F25: 2885876
A26: (-) Investimentos em Imobilizado / Equipamentos | B26: -312500 | C26: -312500 | D26: -312500 | E26: -312500 | F26: -1250000
A27: Caixa Líquido das Atividades de Investimento (FCI) | B27: -312500 | C27: -312500 | D27: -312500 | E27: -312500 | F27: -1250000
A28: (-) Amortização de Empréstimos | B28: -100000 | C28: -100000 | D28: -100000 | E28: -100000 | F28: -400000
A29: (-) Distribuição de Lucros / Pró-labore | B29: -534992 | C29: -571579 | D29: -590681 | E29: -622537 | F29: -2319789
A30: Caixa Líquido das Atividades de Financiamento (FCF) | B30: -634992 | C30: -671579 | D30: -690681 | E30: -722537 | F30: -2719789
A31: Variação Líquida do Caixa no Trimestre | B31: -405844 | C31: -296084 | D31: -238777 | E31: -143209 | F31: -1083913
A32: Caixa Inicial (01/01/2025) | B32: 1800000 | C32: 1394156 | D32: 1098072 | E32: 859296 | F32: -
A33: Caixa Final (31/12/2025) | B33: 1394156 | C33: 1098072 | D33: 859296 | E33: 716087 | F33: -
A34: Aumento ou Redução de Caixa | B34: -405844 | C34: -296084 | D34: -238777 | E34: -143209 | F34: -

Sheet Planilha2
A1: Conta | B1: Descrição | C1: Janeiro | D1: Fevereiro | E1: Março | F1: Abril | G1: Maio | H1: Junho | I1: Julho | J1: Agosto | K1: Setembro | L1: Outubro | M1: Novembro | N1: Dezembro
A2: 3.01.01.03 | B2: Custo dos Bens e Serviços Vendidos | C2: =IFERROR(VLOOKUP(A2,'[3]01.2025'!A:G,6,0),0) -> 0 | D2: =IFERROR(VLOOKUP(A2,'[3]02.2025.2'!A:G,6,0),0) -> 0 | E2: =IFERROR(VLOOKUP(A2,'[3]03.2025.2'!A:G,6,0),0) -> 0 | F2: =IFERROR(VLOOKUP(A2,'[3]04.2025.2'!A:G,6,0),0) -> 0 | G2: =IFERROR(VLOOKUP(A2,'[3]05.2025'!A:G,6,0),0) -> 0 | H2: =IFERROR(VLOOKUP(A2,'[3]06.2025'!A:G,6,0),0) -> 0 | I2: =IFERROR(VLOOKUP(A2,'[3]07.2025.3'!A:G,6,0),0) -> 0 | J2: =IFERROR(VLOOKUP(A2,'[3]08.2025.2'!A:G,6,0),0) -> 0 | K2: =IFERROR(VLOOKUP(A2,'[3]09.2025'!A:G,6,0),0) -> 0
B3: Quant. de pacientes NPC | C3: 1133 | D3: 1160 | E3: 1168 | F3: 1208 | G3: 1262 | H3: 1309 | I3: 1346 | J3: 1413 | K3: 1409
B5: Custo por paciente | C5: =C2/C3 -> 0 | D5: =D2/D3 -> 0 | E5: =E2/E3 -> 0 | F5: =F2/F3 -> 0 | G5: =G2/G3 -> 0 | H5: =H2/H3 -> 0 | I5: =I2/I3 -> 0 | J5: =J2/J3 -> 0 | K5: =K2/K3 -> 0

Sheet Análise
A1: Conta | B1: Descrição | C1: Janeiro | D1: Fevereiro | E1: Março | F1: Abril | G1: Maio | H1: Junho | I1: Julho | J1: Agosto | K1: Setembro | L1: Outubro | M1: Novembro | N1: Dezembro | O1: Nov X Dez | P1: Acumulado | Q1: %
